Workbook
Name __________________SA1: 'Kết quả chấm'!__________________SA1
Name __________________SA2: 'Kết quả chấm'!__________________SA2
Name __________________SA4: 'Kết quả chấm'!__________________SA4
Name _________________SA1: 'Kết quả chấm'!_________________SA1
Name _________________SA2: 'Kết quả chấm'!_________________SA2
Name _________________SA4: 'Kết quả chấm'!_________________SA4
Name ________________SA1: 'Kết quả chấm'!________________SA1
Name ________________SA2: 'Kết quả chấm'!________________SA2
Name ________________SA4: 'Kết quả chấm'!________________SA4
Name _______________SA1: 'Kết quả chấm'!_______________SA1
Name _______________SA2: 'Kết quả chấm'!_______________SA2
Name _______________SA4: 'Kết quả chấm'!_______________SA4
Name ______________SA1: 'Kết quả chấm'!______________SA1
Name ______________SA2: 'Kết quả chấm'!______________SA2
Name ______________SA4: 'Kết quả chấm'!______________SA4
Name _____________SA1: 'Kết quả chấm'!_____________SA1
Name _____________SA2: 'Kết quả chấm'!_____________SA2
Name _____________SA4: 'Kết quả chấm'!_____________SA4
Name ____________SA1: 'Kết quả chấm'!____________SA1
Name ____________SA2: 'Kết quả chấm'!____________SA2
Name ____________SA4: 'Kết quả chấm'!____________SA4
Name ___________SA1: 'Kết quả chấm'!___________SA1
Name ___________SA2: 'Kết quả chấm'!___________SA2
Name ___________SA4: 'Kết quả chấm'!___________SA4
Name __________SA1: 'Kết quả chấm'!__________SA1
Name __________SA2: 'Kết quả chấm'!__________SA2
Name __________SA4: 'Kết quả chấm'!__________SA4
Name _________SA1: 'Kết quả chấm'!_________SA1
Name _________SA2: 'Kết quả chấm'!_________SA2
Name _________SA4: 'Kết quả chấm'!_________SA4
Name ________SA1: 'Kết quả chấm'!________SA1
Name ________SA2: 'Kết quả chấm'!________SA2
Name ________SA4: 'Kết quả chấm'!________SA4
Name _______SA1: 'Kết quả chấm'!_______SA1
Name _______SA2: 'Kết quả chấm'!_______SA2
Name _______SA4: 'Kết quả chấm'!_______SA4
Name ______SA1: 'Kết quả chấm'!______SA1
Name ______SA2: 'Kết quả chấm'!______SA2
Name ______SA4: 'Kết quả chấm'!______SA4
Name _____SA1: 'Kết quả chấm'!_____SA1
Name _____SA2: 'Kết quả chấm'!_____SA2
Name _____SA4: 'Kết quả chấm'!_____SA4
Name ____SA1: 'Kết quả chấm'!____SA1
Name ____SA2: 'Kết quả chấm'!____SA2
Name ____SA4: 'Kết quả chấm'!____SA4
Name ___SA1: 'Kết quả chấm'!___SA1
Name ___SA2: 'Kết quả chấm'!___SA2
Name ___SA4: 'Kết quả chấm'!___SA4
Name __bookmark_1: #REF!
Name __SA1: 'Kết quả chấm'!__SA1
Name __SA2: 'Kết quả chấm'!__SA2
Name __SA4: 'Kết quả chấm'!__SA4
Name _gh1: 'Kết quả chấm'!_gh1
Name _SA1: 'Kết quả chấm'!_SA1
Name _SA2: 'Kết quả chấm'!_SA2
Name _SA4: 'Kết quả chấm'!_SA4
Name â: {"ONGNGOAINHA.xls","Sheet1"}
Name ả4513: #REF!
Name â9000: '[1]Chi tiet'!#REF!
Name chilinh1: '[2]Chi tiet chuan'!$A$2:$A$7163

Sheet Kết quả chấm
A1: Phụ lục: Bảng điểm đánh giá 8 Viettel tỉnh/TP KV2 tháng 7/2025 (Công văn số 1085/VTNet-BQLDAHTVT ngày 26/4/2024)
A3: STT | B3: Tỉnh | C3: Tổng điểm | D3: Điểm KPI hạ tầng | E3: Điểm KPI về pháp lý, triển khai hạ tầng khách hàng và quản lý tài sản | F3: Điểm trung bình tháng 7/2025 | G3: Xếp hạng
A4: 1 | B4: HUE | C4: =D4+E4 | D4: =VLOOKUP(B4,'TH điểm'!$B$8:$D$15,3,0) | E4: =VLOOKUP(B4,'TH điểm'!$AC$8:$AE$15,3,0) | F4: =(D4+E4)/2 | G4: =+RANK(F4,$F$4:$F$11,0)
A5: =A4+1 | B5: QNI | C5: =D5+E5 | D5: =VLOOKUP(B5,'TH điểm'!$B$8:$D$15,3,0) | E5: =VLOOKUP(B5,'TH điểm'!$AC$8:$AE$15,3,0) | F5: =(D5+E5)/2 | G5: =+RANK(F5,$F$4:$F$11,0)
A6: =A5+1 | B6: DNG | C6: =D6+E6 | D6: =VLOOKUP(B6,'TH điểm'!$B$8:$D$15,3,0) | E6: =VLOOKUP(B6,'TH điểm'!$AC$8:$AE$15,3,0) | F6: =(D6+E6)/2 | G6: =+RANK(F6,$F$4:$F$11,0)
A7: =A6+1 | B7: DLK | C7: =D7+E7 | D7: =VLOOKUP(B7,'TH điểm'!$B$8:$D$15,3,0) | E7: =VLOOKUP(B7,'TH điểm'!$AC$8:$AE$15,3,0) | F7: =(D7+E7)/2 | G7: =+RANK(F7,$F$4:$F$11,0)
A8: =A7+1 | B8: GLI | C8: =D8+E8 | D8: =VLOOKUP(B8,'TH điểm'!$B$8:$D$15,3,0) | E8: =VLOOKUP(B8,'TH điểm'!$AC$8:$AE$15,3,0) | F8: =(D8+E8)/2 | G8: =+RANK(F8,$F$4:$F$11,0)
A9: =A8+1 | B9: KHA | C9: =D9+E9 | D9: =VLOOKUP(B9,'TH điểm'!$B$8:$D$15,3,0) | E9: =VLOOKUP(B9,'TH điểm'!$AC$8:$AE$15,3,0) | F9: =(D9+E9)/2 | G9: =+RANK(F9,$F$4:$F$11,0)
A10: =A9+1 | B10: QTI | C10: =D10+E10 | D10: =VLOOKUP(B10,'TH điểm'!$B$8:$D$15,3,0) | E10: =VLOOKUP(B10,'TH điểm'!$AC$8:$AE$15,3,0) | F10: =(D10+E10)/2 | G10: =+RANK(F10,$F$4:$F$11,0)
A11: =A10+1 | B11: LDG | C11: =D11+E11 | D11: =VLOOKUP(B11,'TH điểm'!$B$8:$D$15,3,0) | E11: =VLOOKUP(B11,'TH điểm'!$AC$8:$AE$15,3,0) | F11: =(D11+E11)/2 | G11: =+RANK(F11,$F$4:$F$11,0)

Sheet TH điểm
A1: Phụ lục 01: Bảng điểm đánh giá KPI công tác kỹ thuật 8 Viettel tỉnh/TP thuộc KV2 tháng 7/2025
A3: STT | B3: Tỉnh | C3: Nhóm chỉ tiêu PTHT | AC3: Tỉnh | AD3: Nhóm chỉ tiêu KPI về pháp lý, triển khai hạ tầng khách hàng và quản lý tài sản của VTNet, VTT, VTS
C4: Điểm phân bổ theo chỉ tiêu | D4: Điểm đạt | E4: Chỉ tiêu triển khai BTS | G4: Chỉ tiêu triển khai GPON (hạ tầng) | I4: Chỉ tiêu triển khai dự án tòa nhà, KĐT&KCN đảm bảo kinh doanh | K4: Chỉ tiêu triển khai truyền dẫn | M4: Nâng cao chất lượng mạng | O4: Nghiệm thu, BGTS | Q4: Kiểm soát CLCT | S4: Củng cố, bảo dưỡng, cơ điện | U4: Chỉ tiêu lập HSHC và QT điện tử | W4: Các KPI quy trình | Y4: Quyết toán công trình/thanh lý hợp đồng ủy quyền | AA4: Quản lý chi phí | AD4: Điểm phân bổ theo chỉ tiêu | AE4: Điểm đạt | AF4: KPI đảm bảo công tác pháp lý | AH4: KPI quản lý, điều hành, nề nếp phối hợp | AJ4: Tỷ lệ SR hoàn thành xử lý đúng hạn | AL4: Số trạm 4G giao trong quý có TU đạt ngưỡng sử dụng hiệu quả | AN4: Đánh giá công tác quản lý kho, tài sản
E5: Chỉ tiêu PS vị trí, CS, XD, thuê trạm... | G5: Chỉ tiêu thiết kế, hàn nối, nhập NIMS GPON | I5: Chỉ tiêu triển khai truyền dẫn ngầm, treo | K5: Chỉ tiêu triển khai các KH nâng cao CLM, LHSK, thu/rút thiết bị… | M5: Các chỉ tiêu kiên cố: Cột quá tải trọng, xây nhà máy nổ, nhà X4, kiên cố cơ điện…. | O5: Nề nếp, hình ảnh; khắc phục lỗi, KPI kiểm tra | Q5: Nghiệm thu các CT, BGTS các CT | S5: Các chỉ tiêu HCQT HĐ Vtnet, tỉnh ký HĐ | W5: Các chỉ tiêu HCQT HĐ Vtnet, tỉnh ký HĐ | Y5: Các chỉ tiêu HCQT HĐ Vtnet, tỉnh ký HĐ | AA5: Các chỉ tiêu HCQT HĐ Vtnet, tỉnh ký HĐ | AF5: Chỉ tiêu PS vị trí, CS, XD, thuê trạm... | AH5: Chỉ tiêu thiết kế, hàn nối, nhập NIMS GPON | AJ5: Chỉ tiêu triển khai truyền dẫn ngầm, treo | AL5: Chỉ tiêu triển khai các KH nâng cao CLM, LHSK, thu/rút thiết bị… | AN5: Các chỉ tiêu kiên cố: Cột quá tải trọng, xây nhà máy nổ, nhà X4, kiên cố cơ điện….
E6: Điểm phân bổ theo chỉ tiêu | F6: Điểm đạt | G6: Điểm phân bổ theo chỉ tiêu | H6: Điểm đạt | I6: Điểm phân bổ theo chỉ tiêu | J6: Điểm đạt | K6: Điểm phân bổ theo chỉ tiêu | L6: Điểm đạt | M6: Điểm phân bổ theo chỉ tiêu | N6: Điểm đạt | O6: Điểm phân bổ theo chỉ tiêu | P6: Điểm đạt | Q6: Điểm phân bổ theo chỉ tiêu | R6: Điểm đạt | S6: Điểm phân bổ theo chỉ tiêu | T6: Điểm đạt | U6: Điểm phân bổ theo chỉ tiêu | V6: Điểm đạt | W6: Điểm phân bổ theo chỉ tiêu | X6: Điểm đạt | Y6: Điểm phân bổ theo chỉ tiêu | Z6: Điểm đạt | AA6: Điểm phân bổ theo chỉ tiêu | AB6: Điểm đạt | AF6: Điểm phân bổ theo chỉ tiêu | AG6: Điểm đạt | AH6: Điểm phân bổ theo chỉ tiêu | AI6: Điểm đạt | AJ6: Điểm phân bổ theo chỉ tiêu | AK6: Điểm đạt | AL6: Điểm phân bổ theo chỉ tiêu | AM6: Điểm đạt | AN6: Điểm phân bổ theo chỉ tiêu | AO6: Điểm đạt
A8: 1 | B8: DLK | C8: =E8+G8+I8+K8+M8+O8+Q8+S8+ U8+ W8+Y8+AA8 | D8: =F8+H8+J8+L8+N8+P8+R8+T8+ V8+ X8+Z8+AB8 | E8: 0.73703704 | F8: 0.52222222 | G8: 0.41481481 | H8: 0.41481481 | I8: 0 | J8: 0 | K8: 0.23703704 | L8: 0.23703704 | M8: 0.30740741 | N8: 0.061481481 | O8: 0.53703704 | P8: 0.45111111 | Q8: 0.31481481 | R8: 0.31481481 | S8: 0.42962963 | T8: 0.40814815 | U8: 0.41481481 | V8: 0.41481481 | W8: 0.50740741 | X8: 0.4 | Y8: 0.5 | Z8: 0.1 | AA8: 0.6 | AB8: 0.6 | AC8: DLK | AD8: =AF8+AH8+AJ8+AL8+AN8 | AE8: =AG8+AI8+AK8+AM8+AO8 | AF8: 0.5 | AG8: 0.5 | AH8: 0.4 | AI8: 0.4 | AJ8: 0.5 | AK8: 0.5 | AL8: 0.5 | AM8: 0.5 | AN8: 0.6 | AO8: 0.45
A9: =A8+1 | B9: DNG | C9: =E9+G9+I9+K9+M9+O9+Q9+S9+ U9+ W9+Y9+AA9 | D9: =F9+H9+J9+L9+N9+P9+R9+T9+ V9+ X9+Z9+AB9 | E9: 0.7 | F9: 0.44 | G9: 0.4 | H9: 0.4 | I9: 0.2 | J9: 0.2 | K9: 0.2 | L9: 0.2 | M9: 0.3 | N9: 0.16 | O9: 0.5 | P9: 0.34 | Q9: 0.3 | R9: 0.3 | S9: 0.4 | T9: 0.26 | U9: 0.4 | V9: 0.3 | W9: 0.5 | X9: 0.4 | Y9: 0.5 | Z9: 0.4 | AA9: 0.6 | AB9: 0.6 | AC9: DNG | AD9: =AF9+AH9+AJ9+AL9+AN9 | AE9: =AG9+AI9+AK9+AM9+AO9 | AF9: 0.5 | AG9: 0.5 | AH9: 0.4 | AI9: 0.35 | AJ9: 0.5 | AK9: 0.5 | AL9: 0.5 | AM9: 0.5 | AN9: 0.6 | AO9: 0.48
A10: =A9+1 | B10: GLI | C10: =E10+G10+I10+K10+M10+O10+Q10+S10+ U10+ W10+Y10+AA10 | D10: =F10+H10+J10+L10+N10+P10+R10+T10+ V10+ X10+Z10+AB10 | E10: 0.7 | F10: 0.54 | G10: 0.4 | H10: 0.4 | I10: 0.2 | J10: 0.2 | K10: 0.2 | L10: 0.2 | M10: 0.3 | N10: 0.06 | O10: 0.5 | P10: 0.36 | Q10: 0.3 | R10: 0.26 | S10: 0.4 | T10: 0.18 | U10: 0.4 | V10: 0.3 | W10: 0.5 | X10: 0.45 | Y10: 0.5 | Z10: 0.1 | AA10: 0.6 | AB10: 0.6 | AC10: GLI | AD10: =AF10+AH10+AJ10+AL10+AN10 | AE10: =AG10+AI10+AK10+AM10+AO10 | AF10: 0.5 | AG10: 0.5 | AH10: 0.4 | AI10: 0.4 | AJ10: 0.5 | AK10: 0.5 | AL10: 0.5 | AM10: 0.5 | AN10: 0.6 | AO10: 0.53
A11: =A10+1 | B11: HUE | C11: =E11+G11+I11+K11+M11+O11+Q11+S11+ U11+ W11+Y11+AA11 | D11: =F11+H11+J11+L11+N11+P11+R11+T11+ V11+ X11+Z11+AB11 | E11: 0.7 | F11: 0.68 | G11: 0.4 | H11: 0.4 | I11: 0.2 | J11: 0.2 | K11: 0.2 | L11: 0.2 | M11: 0.3 | N11: 0.26 | O11: 0.5 | P11: 0.3 | Q11: 0.3 | R11: 0.3 | S11: 0.4 | T11: 0.28 | U11: 0.4 | V11: 0.4 | W11: 0.5 | X11: 0.4 | Y11: 0.5 | Z11: 0.4 | AA11: 0.6 | AB11: 0.6 | AC11: HUE | AD11: =AF11+AH11+AJ11+AL11+AN11 | AE11: =AG11+AI11+AK11+AM11+AO11 | AF11: 0.5 | AG11: 0.5 | AH11: 0.4 | AI11: 0.35 | AJ11: 0.5 | AK11: 0.5 | AL11: 0.5 | AM11: 0.5 | AN11: 0.6 | AO11: 0.5
A12: =A11+1 | B12: KHA | C12: =E12+G12+I12+K12+M12+O12+Q12+S12+ U12+ W12+Y12+AA12 | D12: =F12+H12+J12+L12+N12+P12+R12+T12+ V12+ X12+Z12+AB12 | E12: 0.7 | F12: 0.6 | G12: 0.4 | H12: 0.4 | I12: 0.2 | J12: 0.2 | K12: 0.2 | L12: 0.168 | M12: 0.3 | N12: 0.26 | O12: 0.5 | P12: 0.28 | Q12: 0.3 | R12: 0.255 | S12: 0.4 | T12: 0.16 | U12: 0.4 | V12: 0.14 | W12: 0.5 | X12: 0.4 | Y12: 0.5 | Z12: 0.1 | AA12: 0.6 | AB12: 0.6 | AC12: KHA | AD12: =AF12+AH12+AJ12+AL12+AN12 | AE12: =AG12+AI12+AK12+AM12+AO12 | AF12: 0.5 | AG12: 0.5 | AH12: 0.4 | AI12: 0.4 | AJ12: 0.5 | AK12: 0.5 | AL12: 0.5 | AM12: 0.5 | AN12: 0.6 | AO12: 0.45
A13: =A12+1 | B13: LDG | C13: =E13+G13+I13+K13+M13+O13+Q13+S13+ U13+ W13+Y13+AA13 | D13: =F13+H13+J13+L13+N13+P13+R13+T13+ V13+ X13+Z13+AB13 | E13: 0.73846154 | F13: 0.29692308 | G13: 0.41538462 | H13: 0.41538462 | I13: 0 | J13: 0 | K13: 0.23846154 | L13: 0.20030769 | M13: 0.30769231 | N13: 0.061538462 | O13: 0.53846154 | P13: 0.23692308 | Q13: 0.30769231 | R13: 0.30769231 | S13: 0.43076923 | T13: 0.19384615 | U13: 0.41538462 | V13: 0.14538462 | W13: 0.50769231 | X13: 0.4 | Y13: 0.5 | Z13: 0.1 | AA13: 0.6 | AB13: 0.6 | AC13: LDG | AD13: =AF13+AH13+AJ13+AL13+AN13 | AE13: =AG13+AI13+AK13+AM13+AO13 | AF13: 0.5 | AG13: 0.5 | AH13: 0.4 | AI13: 0.2 | AJ13: 0.5 | AK13: 0.5 | AL13: 0.5 | AM13: 0.5 | AN13: 0.6 | AO13: 0.45
A14: =A13+1 | B14: QNI | C14: =E14+G14+I14+K14+M14+O14+Q14+S14+ U14+ W14+Y14+AA14 | D14: =F14+H14+J14+L14+N14+P14+R14+T14+ V14+ X14+Z14+AB14 | E14: 0.7 | F14: 0.64 | G14: 0.4 | H14: 0.28 | I14: 0.2 | J14: 0.2 | K14: 0.2 | L14: 0.2 | M14: 0.3 | N14: 0.26 | O14: 0.5 | P14: 0.36 | Q14: 0.3 | R14: 0.3 | S14: 0.4 | T14: 0.22 | U14: 0.4 | V14: 0.4 | W14: 0.5 | X14: 0.4 | Y14: 0.5 | Z14: 0.4 | AA14: 0.6 | AB14: 0.6 | AC14: QNI | AD14: =AF14+AH14+AJ14+AL14+AN14 | AE14: =AG14+AI14+AK14+AM14+AO14 | AF14: 0.5 | AG14: 0.5 | AH14: 0.4 | AI14: 0.35 | AJ14: 0.5 | AK14: 0.5 | AL14: 0.5 | AM14: 0.5 | AN14: 0.6 | AO14: 0.51
A15: =A14+1 | B15: QTI | C15: =E15+G15+I15+K15+M15+O15+Q15+S15+ U15+ W15+Y15+AA15 | D15: =F15+H15+J15+L15+N15+P15+R15+T15+ V15+ X15+Z15+AB15 | E15: 0.73703704 | F15: 0.46777778 | G15: 0.41481481 | H15: 0.31185185 | I15: 0 | J15: 0 | K15: 0.23703704 | L15: 0.23703704 | M15: 0.30740741 | N15: 0.16148148 | O15: 0.53703704 | P15: 0.2362963 | Q15: 0.31481481 | R15: 0.18888889 | S15: 0.42962963 | T15: 0.25777778 | U15: 0.41481481 | V15: 0.24888889 | W15: 0.50740741 | X15: 0.4 | Y15: 0.5 | Z15: 0.4 | AA15: 0.6 | AB15: 0.6 | AC15: QTI | AD15: =AF15+AH15+AJ15+AL15+AN15 | AE15: =AG15+AI15+AK15+AM15+AO15 | AF15: 0.5 | AG15: 0.5 | AH15: 0.4 | AI15: 0.4 | AJ15: 0.5 | AK15: 0.5 | AL15: 0.5 | AM15: 0.5 | AN15: 0.6 | AO15: 0.45

Sheet VTT
A1: Tỉnh | B1: 1. Báo cáo các khó khăn vướng mắc theo quy định 273104 | C1: 2. Tiến độ hạ tầng trạm 5G | D1: 3. Tiến độ hạ tầng 4G new-site | E1: 4. Kiểm soát công tác VHKT dịch vụ CĐBR | F1: 5. Thời gian xử lý sự cố Vtracking, Stracking | G1: Tổng điểm VTT
A2: CBG | B2: 0.1 | C2: 0.3 | D2: 0.16 | E2: 0.6 | G2: =E2+D2+C2+B2 | H2: =SUM(B2:F2)=G2 | I2: =VLOOKUP(A2,'[9]Diem TH tinh Thang'!$B$4:$B$36,1,0)
A3: DBN | B3: 0.1 | C3: 0.14 | D3: 0.24 | E3: 0.6 | G3: =E3+D3+C3+B3 | H3: =SUM(B3:F3)=G3 | I3: =VLOOKUP(A3,'[9]Diem TH tinh Thang'!$B$4:$B$36,1,0)
A4: HNI | B4: 0.2 | C4: 0.4 | D4: 0.64 | E4: 1.4 | G4: =E4+D4+C4+B4 | H4: =SUM(B4:F4)=G4 | I4: =VLOOKUP(A4,'[9]Diem TH tinh Thang'!$B$4:$B$36,1,0)
A5: LCU | B5: 0.1 | C5: 0.3 | D5: 0.24 | E5: 0.6 | G5: =E5+D5+C5+B5 | H5: =SUM(B5:F5)=G5 | I5: =VLOOKUP(A5,'[9]Diem TH tinh Thang'!$B$4:$B$36,1,0)
A6: LSN | B6: 0.1 | C6: 0.3 | D6: 0.2 | E6: 0.6 | G6: =E6+D6+C6+B6 | H6: =SUM(B6:F6)=G6 | I6: =VLOOKUP(A6,'[9]Diem TH tinh Thang'!$B$4:$B$36,1,0)
A7: NAN | B7: 0.1 | C7: 0.3 | D7: 0.32 | E7: 0.6 | G7: =E7+D7+C7+B7 | H7: =SUM(B7:F7)=G7 | I7: =VLOOKUP(A7,'[9]Diem TH tinh Thang'!$B$4:$B$36,1,0)
A8: QNH | B8: 0.1 | C8: 0.18 | D8: 0.32 | E8: 0.6 | G8: =E8+D8+C8+B8 | H8: =SUM(B8:F8)=G8 | I8: =VLOOKUP(A8,'[9]Diem TH tinh Thang'!$B$4:$B$36,1,0)
A9: SLA | B9: 0.1 | C9: 0.14 | D9: 0.32 | E9: 0.6 | G9: =E9+D9+C9+B9 | H9: =SUM(B9:F9)=G9 | I9: =VLOOKUP(A9,'[9]Diem TH tinh Thang'!$B$4:$B$36,1,0)
A10: THA | B10: 0.1 | C10: 0.3 | D10: 0.24 | E10: 0.6 | G10: =E10+D10+C10+B10 | H10: =SUM(B10:F10)=G10 | I10: =VLOOKUP(A10,'[9]Diem TH tinh Thang'!$B$4:$B$36,1,0)
A11: TQG | B11: 0.1 | C11: 0.3 | D11: 0.4 | E11: 0.6 | G11: =E11+D11+C11+B11 | H11: =SUM(B11:F11)=G11 | I11: =VLOOKUP(A11,'[9]Diem TH tinh Thang'!$B$4:$B$36,1,0)
A12: LCI | B12: 0.1 | C12: 0.3 | D12: 0.32 | E12: 0.6 | G12: =E12+D12+C12+B12 | H12: =SUM(B12:F12)=G12 | I12: =VLOOKUP(A12,'[9]Diem TH tinh Thang'!$B$4:$B$36,1,0)
A13: TNN | B13: 0.1 | C13: 0.3 | D13: 0.4 | E13: 0.6 | G13: =E13+D13+C13+B13 | H13: =SUM(B13:F13)=G13 | I13: =VLOOKUP(A13,'[9]Diem TH tinh Thang'!$B$4:$B$36,1,0)
... A35: CMU | B35: 0.1 | C35: 0.3 | D35: 0.32 | E35: 0.6 | G35: =E35+D35+C35+B35 | H35: =SUM(B35:F35)=G35 | I35: =VLOOKUP(A35,'[9]Diem TH tinh Thang'!$B$4:$B$36,1,0)

Sheet VTS
A1: STT | B1: Tỉnh | C1: Tổng điểm | D1: Tỷ lệ hoàn thành SR khảo sát, thiết kế, lập dự toán kinh phí nhân công, vật tư triển khai cáp nhiều đôi | E1: Tỷ lệ hoàn thành SR ký hợp đồng và điều hành đối tác triển khai cáp nhiều đôi | F1: Tỷ lệ hoàn thành SR hoàn công quyết toán các kênh triển khai cáp lớn
A2: 1 | B2: AGG | C2: 1 | D2: 0.4 | E2: 0.3 | F2: 0.3 | G2: =SUM(D2:F2)=C2 | H2: =VLOOKUP(B2,'[9]Diem TH tinh Thang'!$B$3:$B$36,1,0)
A3: 2 | B3: BNH | C3: 1 | D3: 0.4 | E3: 0.3 | F3: 0.3 | G3: =SUM(D3:F3)=C3 | H3: =VLOOKUP(B3,'[9]Diem TH tinh Thang'!$B$3:$B$36,1,0)
A4: 3 | B4: CBG | C4: 1 | D4: 0.4 | E4: 0.3 | F4: 0.3 | G4: =SUM(D4:F4)=C4 | H4: =VLOOKUP(B4,'[9]Diem TH tinh Thang'!$B$3:$B$36,1,0)
A5: 4 | B5: CMU | C5: 1 | D5: 0.4 | E5: 0.3 | F5: 0.3 | G5: =SUM(D5:F5)=C5 | H5: =VLOOKUP(B5,'[9]Diem TH tinh Thang'!$B$3:$B$36,1,0)
A6: 5 | B6: CTO | C6: 1 | D6: 0.4 | E6: 0.3 | F6: 0.3 | G6: =SUM(D6:F6)=C6 | H6: =VLOOKUP(B6,'[9]Diem TH tinh Thang'!$B$3:$B$36,1,0)
A7: 6 | B7: DBN | C7: 1 | D7: 0.4 | E7: 0.3 | F7: 0.3 | G7: =SUM(D7:F7)=C7 | H7: =VLOOKUP(B7,'[9]Diem TH tinh Thang'!$B$3:$B$36,1,0)
A8: 7 | B8: DLK | C8: 1 | D8: 0.4 | E8: 0.3 | F8: 0.3 | G8: =SUM(D8:F8)=C8 | H8: =VLOOKUP(B8,'[9]Diem TH tinh Thang'!$B$3:$B$36,1,0)
A9: 8 | B9: DNG | C9: 1 | D9: 0.4 | E9: 0.3 | F9: 0.3 | G9: =SUM(D9:F9)=C9 | H9: =VLOOKUP(B9,'[9]Diem TH tinh Thang'!$B$3:$B$36,1,0)
A10: 9 | B10: DNI | C10: 1 | D10: 0.4 | E10: 0.3 | F10: 0.3 | G10: =SUM(D10:F10)=C10 | H10: =VLOOKUP(B10,'[9]Diem TH tinh Thang'!$B$3:$B$36,1,0)
A11: 10 | B11: DTP | C11: 1 | D11: 0.4 | E11: 0.3 | F11: 0.3 | G11: =SUM(D11:F11)=C11 | H11: =VLOOKUP(B11,'[9]Diem TH tinh Thang'!$B$3:$B$36,1,0)
A12: 11 | B12: GLI | C12: 1 | D12: 0.4 | E12: 0.3 | F12: 0.3 | G12: =SUM(D12:F12)=C12 | H12: =VLOOKUP(B12,'[9]Diem TH tinh Thang'!$B$3:$B$36,1,0)
A13: 12 | B13: HCM | C13: 2 | D13: 0.8 | E13: 0.6 | F13: 0.6 | G13: =SUM(D13:F13)=C13 | H13: =VLOOKUP(B13,'[9]Diem TH tinh Thang'!$B$3:$B$36,1,0)
... A35: 34 | B35: VLG | C35: 1 | D35: 0.4 | E35: 0.3 | F35: 0.3 | G35: =SUM(D35:F35)=C35 | H35: =VLOOKUP(B35,'[9]Diem TH tinh Thang'!$B$3:$B$36,1,0)

Sheet Tỉnh T7
A1: T7 | B1: DLK | C1: KH | D1: Thực hiện | E1: %TH/KH | F1: Điểm phân bổ | G1: Điểm đạt | H1: Đạt/KPI | I1: T6 | J1: T7/T6 | K1: Lũy kế 2025 | L1: Thực hiện năm 2024 | M1: 2025/2024
B2: Tổng điểm | F2: =F3+F16+F22+F27 | G2: =G3+G16+G22+G27 | H2: =H3+H16+H22+H27
A3: I | B3: Nhóm chỉ tiêu PTHT | F3: =SUM(F4:F15) | G3: =SUM(G4:G15) | H3: =SUM(H4:H15)
A4: 1 | B4: Chỉ tiêu triển khai BTS | C4: =BC_chi_tiet!G3 | D4: =BC_chi_tiet!H3 | E4: =IF(D4> 0,D4/C4,0) | F4: 0.73703704 | G4: 0.52222222 | H4: =G4-F4
A5: 2 | B5: Chỉ tiêu triển khai GPON (hạ tầng) | C5: =BC_chi_tiet!G8 | D5: =BC_chi_tiet!H8 | E5: =IF(D5> 0,D5/C5,0) | F5: 0.41481481 | G5: 0.41481481 | H5: =G5-F5
A6: 3 | B6: Chỉ tiêu triển khai dự án tòa nhà, KĐT&KCN đảm bảo kinh doanh | F6: 0 | G6: 0 | H6: =G6-F6
A7: 4 | B7: Chỉ tiêu triển khai truyền dẫn | C7: =SUM(BC_chi_tiet!G4:G7) | D7: =SUM(BC_chi_tiet!H4:H7) | E7: =IF(D7> 0,D7/C7,0) | F7: 0.23703704 | G7: 0.23703704 | H7: =G7-F7
A8: 5 | B8: Nâng cao chất lượng mạng | E8: =IF(D8> 0,D8/C8,0) | F8: 0.30740741 | G8: 0.061481481 | H8: =G8-F8
A9: 6 | B9: Nghiệm thu, BGTS | E9: =IF(D9> 0,D9/C9,0) | F9: 0.53703704 | G9: 0.45111111 | H9: =G9-F9
A10: 7 | B10: Kiểm soát CLCT | E10: =IF(D10> 0,D10/C10,0) | F10: 0.31481481 | G10: 0.31481481 | H10: =G10-F10
A11: 8 | B11: Củng cố, bảo dưỡng, cơ điện | E11: =IF(D11> 0,D11/C11,0) | F11: 0.42962963 | G11: 0.40814815 | H11: =G11-F11
A12: 9 | B12: Chỉ tiêu lập HSHC và QT điện tử | F12: 0.41481481 | G12: 0.41481481 | H12: =G12-F12
A13: 10 | B13: Các KPI quy trình | F13: 0.50740741 | G13: 0.4 | H13: =G13-F13
A14: 11 | B14: Quyết toán công trình/thanh lý hợp đồng ủy quyền | F14: 0.5 | G14: 0.1 | H14: =G14-F14
A15: 12 | B15: Quản lý chi phí | F15: 0.6 | G15: 0.6 | H15: =G15-F15
A16: II | B16: Nhóm chỉ tiêu KPI về pháp lý, triển khai hạ tầng khách hàng và quản lý tài sản của VTNet, VTT, VTS | F16: =SUM(F17:F21) | G16: =SUM(G17:G21) | H16: =SUM(H17:H21)
A17: 1 | B17: KPI đảm bảo công tác pháp lý | F17: 0.5 | G17: 0.5 | H17: =G17-F17
A18: 2 | B18: KPI quản lý, điều hành, nề nếp phối hợp | F18: 0.4 | G18: 0.4 | H18: =G18-F18
A19: 3 | B19: Tỷ lệ SR hoàn thành xử lý đúng hạn | F19: 0.5 | G19: 0.5 | H19: =G19-F19
A20: 4 | B20: Số trạm 4G giao trong quý có TU đạt ngưỡng sử dụng hiệu quả | F20: 0.5 | G20: 0.5 | H20: =G20-F20
A21: 5 | B21: Đánh giá công tác quản lý kho, tài sản | F21: 0.6 | G21: 0.45 | H21: =G21-F21
A22: III | B22: VTT | F22: =SUM(F23:F26) | G22: =SUM(G23:G26) | H22: =SUM(H23:H26)
A23: 1 | B23: 1. Báo cáo các khó khăn vướng mắc theo quy định 273104 | F23: 0.1 | G23: 0.1 | H23: =G23-F23
A24: 2 | B24: 2. Tiến độ hạ tầng trạm 5G | F24: 0.3 | G24: 0.3 | H24: =G24-F24
A25: 3 | B25: 3. Tiến độ hạ tầng 4G new-site | F25: 0.3 | G25: 0.32 | H25: =G25-F25
A26: 4 | B26: 4. Kiểm soát công tác VHKT dịch vụ CĐBR | F26: 0.6 | G26: 0.6 | H26: =G26-F26
A27: IV | B27: VTS | F27: =SUM(F28:F30) | G27: =SUM(G28:G30) | H27: =SUM(H28:H30)
A28: 1 | B28: Tỷ lệ hoàn thành SR khảo sát, thiết kế, lập dự toán kinh phínhân công, vật tư triển khai cáp nhiều đôi | F28: 0.4 | G28: 0.4 | H28: =G28-F28
A29: 2 | B29: Tỷ lệ hoàn thành SR ký hợp đồng và điều hành đối tác triển khai cáp nhiều đôi | F29: 0.3 | G29: 0.3 | H29: =G29-F29
A30: 3 | B30: Tỷ lệ hoàn thành SR hoàn công quyết toán các kênh triển khai cáp lớn | F30: 0.3 | G30: 0.3 | H30: =G30-F30

Sheet BC_chi_tiet
A1: Nội dung | C1: ĐVT | G1: Tháng 7/2025 | J1: Quý 3/2025 | M1: Năm 2025 | Q1: id
D2: TH Quý 1 | E2: TH Quý 2 | F2: TH Quý 3 | G2: Kế hoạch | H2: Thực hiện | I2: % HT | J2: Kế hoạch | K2: Thực hiện | L2: % HT | M2: Kế hoạch | N2: Thực hiện | O2: % HT | P2: Nhân sự thực hiện
A3: BTS | B3: Phát sóng vị trí BTS | C3: Vị trí | G3: 18 | H3: 19 | I3: 1.0555556 | P3: đc Duy + Đạt | Q3: phatsongvitribts
A4: Triển khai truyền dẫn | B4: Kéo cáp ngầm | C4: Km | I4: 0 | P4: =Meta!C14 | Q4: keocapngam | R4: =Meta!C16 | S4: =Meta!C17 | T4: =Meta!C18 | U4: =Meta!C19 | V4: =Meta!C20 | W4: =Meta!C21 | X4: =Meta!C22 | Y4: =Meta!C23
B5: Tuyến ngầm ĐVSD | C5: Tuyến | I5: 0 | P5: =Meta!D14 | Q5: tuyenngamđvsd | R5: =Meta!D16 | S5: =Meta!D17 | T5: =Meta!D18 | U5: =Meta!D19 | V5: =Meta!D20 | W5: =Meta!D21 | X5: =Meta!D22 | Y5: =Meta!D23
B6: Kéo cáp treo | C6: Km | I6: 0 | P6: đc Thạch | Q6: keocaptreo
B7: Tuyến treo ĐVSD | C7: Tuyến | I7: 0 | P7: đc Thạch | Q7: tuyentreođvsd
A8: GPON | B8: Nhập NIMS GPON | C8: Cổng | I8: 0 | P8: đc Hiền + đc Tàu | Q8: nhapnimsgpon
A9: Kiên cố, củng cố | B9: Kiên cố cột quá tải trọng | C9: GP | I9: 0 | P9: đc Hà | Q9: kiencocotquataitrong
B10: Củng cố cột và nhà trạm BTS | C10: Trạm | I10: 0 | P10: đc Hà | Q10: cungcocotvanhatrambts
B11: Củng cố tuyến truyền dẫn | C11: Tuyến | I11: 0 | P11: đc Chánh | Q11: cungcotuyentruyendan
B12: Củng cố tuyến CĐBR | C12: Tuyến | G12: 20 | H12: 18 | I12: 0.9 | P12: đc Chánh | Q12: cungcotuyencđbr
A13: Quản lý tài sản | B13: BGTS Công trình | G13: 121 | H13: 15 | I13: 0.12396694 | P13: đc Hòa + Sơn | Q13: bgtscongtrinh
B14: Bàn giao tài sản công trình CT BTS (theo CT nghiệm thu hàng tháng) | G14: 59 | H14: 0 | I14: 0 | P14: đc Hòa + Sơn | Q14: bangiaotaisancongtrinhctbts (theoctnghiemthuhangthang)
B15: Bàn giao tài sản công trình CT truyền dẫn (theo CT nghiệm thu hàng tháng) | G15: 0 | H15: 0 | I15: 0 | P15: đc Hòa + Sơn | Q15: bangiaotaisancongtrinhcttruyendan (theoctnghiemthuhangthang)
B16: Bàn giao tài sản công trình CT GPON (theo CT nghiệm thu hàng tháng) | G16: 0 | H16: 0 | I16: 0 | P16: đc Hòa + Sơn | Q16: bangiaotaisancongtrinhctgpon (theoctnghiemthuhangthang)
B17: Bàn giao tài sản công trình CT cơ điện | G17: 15 | H17: 15 | I17: 1 | P17: đc Hòa + Sơn | Q17: bangiaotaisancongtrinhctcođien
B18: Kiểm tra tài sản trạm | I18: 0 | P18: đc Hòa + Sơn | Q18: kiemtrataisantram
A19: Hoàn công thanh quyết toán | B19: Lập hồ sơ theo tiến độ thi công | G19: 0 | H19: 0 | I19: 0 | P19: đc Thạch + Thuận | Q19: laphosotheotienđothicong
B20: Công trình BTS | I20: 0 | P20: đc Thạch + Thuận | Q20: congtrinhbts
B21: Công trình cơ điện | I21: 0 | P21: đc Thạch + Thuận | Q21: congtrinhcođien
B22: Hoàn thành bộ hồ sơ hoàn công đến BC4A | G22: 0 | H22: 0 | I22: 0 | P22: đc Thạch + Thuận | Q22: hoanthanhbohosohoancongđenbc4a
B23: Công trình BTS | P23: đc Thạch + Thuận | Q23: congtrinhbts
B24: Công trình cơ điện | P24: đc Thạch + Thuận | Q24: congtrinhcođien
A25: Tòa nhà, KCN, KĐT | B25: Triển khai dự án mới | C25: DA | P25: đc Hiền + đc Tàu | Q25: trienkhaiduanmoi

Sheet Meta
A1: id | B1: Ten | C1: Thang | E1: Quy | G1: Nam
C2: KH | D2: TH | E2: KH | F2: TH | G2: KH | H2: TH
A3: 1 | B3: phatsongvitribts | C3: 18 | D3: 19
A4: 2 | B4: keocapngam
A5: 3 | B5: tuyenngamđvsd
A6: 4 | B6: keocaptreo
A7: 5 | B7: tuyentreođvsd
A8: 6 | B8: nhapnimsgpon
A9: 7 | B9: kiencocotquataitrong
A10: 8 | B10: cungcocotvanhatrambts
A11: 9 | B11: cungcotuyentruyendan
A12: 10 | B12: cungcotuyencđbr | C12: 20 | D12: 18
A13: 11 | B13: bgtscongtrinh | C13: 121 | D13: 15
A14: 12 | B14: bangiaotaisancongtrinhctbts (theoctnghiemthuhangthang) | C14: 59 | D14: 0
A15: 13 | B15: bangiaotaisancongtrinhcttruyendan (theoctnghiemthuhangthang) | C15: 0 | D15: 0
A16: 14 | B16: bangiaotaisancongtrinhctgpon (theoctnghiemthuhangthang) | C16: 0 | D16: 0
A17: 15 | B17: bangiaotaisancongtrinhctcođien | C17: 15 | D17: 15
A18: 16 | B18: kiemtrataisantram
A19: 17 | B19: laphosotheotienđothicong | C19: 0 | D19: 0
A20: 18 | B20: congtrinhbts | C20: 0 | D20: 0
A21: 19 | B21: congtrinhcođien | C21: 1 | D21: 0
A22: 20 | B22: hoanthanhbohosohoancongđenbc4a | C22: 0 | D22: 0
A23: 21 | B23: congtrinhbts
A24: 22 | B24: congtrinhcođien
A25: 23 | B25: trienkhaiduanmoi

Sheet PLI- KPI cham diem tinh
A1: PHỤ LỤC I: DANH SÁCH KPI HẠ TẦNG GIAO CHO GIÁM ĐỐC VIETTEL TỈNH/TP (Kèm theo Công văn số ngày tháng năm 2024)
A2: TT | B2: Thông tin KPI | D2: Mới | H2: Cũ | L2: Tăng/giảm | P2: Phân bổ theo mức | S2: Đơn vị đánh giá trực tiếp | T2: Ghi chú
B3: Tên KPI | C3: Cách đánh giá/chỉ số đo lường | D3: 61 VT tỉnh/TP | F3: VT HNI, HCM | H3: 61 VT tỉnh/TP | J3: VT HNI, HCM | L3: 61 VT tỉnh/TP | N3: VT HNI, HCM | U3: Đầu mối đề xuất
D4: Điểm chấm | E4: Tỷ trọng | F4: Điểm chấm | G4: Tỷ trọng | H4: Điểm chấm | I4: Tỷ trọng | J4: Điểm chấm | K4: Tỷ trọng | L4: Điểm chấm | M4: Tỷ trọng | N4: Điểm chấm | O4: Tỷ trọng | P4: Tối thiểu | Q4: Mong đợi | R4: Thách thức
A5: * | B5: Tổng KPI triển khai hạ tầng | D5: =SUM(D6:D17) | E5: =SUM(E6:E17) | F5: =SUM(F6:F17) | G5: =SUM(G6:G17) | H5: =SUM(H6:H16) | I5: =SUM(I6:I16) | J5: =SUM(J6:J16) | K5: =SUM(K6:K16) | L5: =D5-H5 | M5: =E5-I5 | N5: =F5-J5 | O5: =G5-K5
A6: 1 | B6: Triển khai trạm BTS đảm bảo hạ tầng kinh doanh | C6: =+C20 | D6: =D19 | E6: =+D6/5 | F6: 1.3 | G6: =+F6/7.5 | H6: =H19 | I6: 0.16 | J6: 1.3 | K6: 0.17333333 | L6: =D6-H6 | M6: =E6-I6 | N6: =F6-J6 | O6: =G6-K6 | P6: =+P19 | Q6: =+Q19 | R6: =+R19 | S6: =+S19 | T6: =+T19 | U6: =+U19
A7: =+A6+1 | B7: Triển khai Gpon đảm bảo hạ tầng kinh doanh (bao gồm cả ngoài trời và trong nhà) | C7: =+C26 | D7: =+D25 | E7: =+D7/5 | F7: =+F25 | G7: =+F7/7.5 | H7: =+H25 | I7: =+I25 | J7: =+J25 | K7: =+K25 | L7: =D7-H7 | M7: =E7-I7 | N7: =F7-J7 | O7: =G7-K7 | P7: =+P25 | Q7: =+Q25 | R7: =+R25 | S7: =+S25 | T7: =+T25 | U7: =+U25
A8: =+A7+1 | B8: Triển khai dự án tòa nhà, khu đô thị, khu công nghiệp đảm bảo kinh doanh | C8: =+C29 | D8: =+D28 | E8: =+D8/5 | F8: =+F28 | G8: =+F8/7.5 | H8: =+H28 | I8: =+I28 | J8: =+J28 | K8: =+K28 | L8: =D8-H8 | M8: =E8-I8 | N8: =F8-J8 | O8: =G8-K8 | P8: =+P28 | Q8: =+Q28 | R8: =+R28 | S8: =+S28 | T8: =+T28 | U8: =+U28 | V8: Giảm 0,1
A9: =+A8+1 | B9: Triển khai truyền dẫn (ngầm/treo) | C9: =+C30 | D9: =+D30 | E9: =+D9/5 | F9: =+F30 | G9: =+F9/7.5 | H9: =+H30 | I9: =+I30 | J9: =+J30 | K9: =+K30 | L9: =D9-H9 | M9: =E9-I9 | N9: =F9-J9 | O9: =G9-K9 | P9: =+P30 | Q9: =+Q30 | R9: =+R30 | S9: =+S30 | T9: =+T30 | U9: =+U30
A10: =+A9+1 | B10: Triển khai các kế hoạch NCCLM, LHSK, thu/rút thiết bị…. | C10: =+C33 | D10: =+D33 | E10: =+D10/5 | F10: =+F33 | G10: =+F10/7.5 | H10: =+H33 | I10: =+I33 | J10: =+J33 | K10: =+K33 | L10: =D10-H10 | M10: =E10-I10 | N10: =F10-J10 | O10: =G10-K10 | P10: =+P33 | Q10: =+Q33 | R10: =+R33 | S10: =+S33 | T10: =+T33 | U10: =+U33
A11: =+A10+1 | B11: Nghiệm thu/giảm tồn tài sản | C11: =+C34 | D11: =+D34 | E11: =+D11/5 | F11: =+F34 | G11: =+F11/7.5 | H11: =+H34 | I11: =+I34 | J11: =+J34 | K11: =+K34 | L11: =D11-H11 | M11: =E11-I11 | N11: =F11-J11 | O11: =G11-K11 | P11: =+P34 | Q11: =+Q34 | R11: =+R34 | S11: =+S34 | T11: =+T34 | U11: =+U34 | V11: Giảm 0,3
A12: =+A11+1 | B12: Kiểm soát chất lượng công trình | C12: =+C38 | D12: =+D38 | E12: =+D12/5 | F12: =+F38 | G12: =+F12/7.5 | H12: =+H38 | I12: =+I38 | J12: =+J38 | K12: =+K38 | L12: =D12-H12 | M12: =E12-I12 | N12: =F12-J12 | O12: =G12-K12 | P12: =+P38 | Q12: =+Q38 | R12: =+R38 | S12: =+S38 | T12: =+T38 | U12: =+U38
A13: =+A12+1 | B13: Củng cố, bảo dưỡng, cơ điện | C13: =+C42 | D13: =+D42 | E13: =+D13/5 | F13: =+F42 | G13: =+F13/7.5 | H13: =+H42 | I13: =+I42 | J13: =+J42 | K13: =+K42 | L13: =D13-H13 | M13: =E13-I13 | N13: =F13-J13 | O13: =G13-K13 | P13: =+P42 | Q13: =+Q42 | R13: =+R42 | S13: =+S42 | T13: =+T42 | U13: =+U42
A14: =+A13+1 | B14: Quyết toán công trình/thanh lý hợp đồng (bao gồm hợp đồng VTNet và hợp đồng ủy quyền) | C14: =+C47 | D14: =+D47 | E14: =+D14/5 | F14: =+F47 | G14: =+F14/7.5 | H14: =+H47 | I14: =+I47 | J14: =+J47 | K14: =+K47 | L14: =D14-H14 | M14: =E14-I14 | N14: =F14-J14 | O14: =G14-K14 | P14: =+P47 | Q14: =+Q47 | R14: =+R47 | S14: =+S47 | T14: =+T47 | U14: =+U47
A15: =+A14+1 | B15: Quản lý chi phí (thanh quyết toán hợp đồng nguồn chi phí VHKT, đàm phán gia hạn, kết quả thực hiện chi phí VHKT) | C15: =+C51 | D15: =+D51 | E15: =+D15/5 | F15: =+F51 | G15: =+F15/7.5 | H15: =+H51 | I15: =+I51 | J15: =+J51 | K15: =+K51 | L15: =D15-H15 | M15: =E15-I15 | N15: =F15-J15 | O15: =G15-K15 | P15: =+P51 | Q15: =+Q51 | R15: =+R51 | S15: =+S51 | T15: =+T51 | U15: =+U51
A16: 11 | B16: Chỉ tiêu lập HSHC và QT điện tử | C16: =C55 | D16: =D55 | E16: =+D16/5 | F16: =F55 | G16: =+F16/7.5 | H16: =H55 | I16: =I55 | J16: =J55 | K16: =K55 | L16: =D16-H16 | M16: =E16-I16 | N16: =F16-J16 | O16: =G16-K16 | P16: =P55 | Q16: =Q55 | R16: =R55
A17: 12 | B17: Các KPI quy trình trọng yếu | C17: Kết quả thực hiện đánh giá theo tỷ lệ KPI hoàn thành: - Dưới 7 KPI đạt: 0 điểm - Từ 07-10 KPI đạt: + Điểm = số KPI đạt * 0,5/10 ( đối với 61 Viettel tỉnh/TP); + Điểm = số KPI đạt * 0,6/10 (đối với Viettel HNI, HCM) | D17: =D59 | E17: =+D17/5 | F17: =F59 | G17: =+F17/7.5 | H17: =H59 | I17: =I59 | J17: =J59 | K17: =K59 | L17: =L59 | M17: =M59 | N17: =N59 | O17: =O59 | T17: Target
A18: * | B18: Chi tiết các KPI con cho KPI chính (Đối với các KPI con mà không có kế hoạch tháng => Điểm phân bổ được chia cho các KPI còn lại) | D18: =+D19+D25+D28+D30+D33+D34+D38+D42+D47+D51+D55+D59 | E18: =+E19+E25+E28+E30+E33+E34+E38+E42+E47+E51+E55+E59 | F18: =+F19+F25+F28+F30+F33+F34+F38+F42+F47+F51+F55+F59 | G18: =+G19+G25+G28+G30+G33+G34+G38+G42+G47+G51+G55+G59 | H18: =+H19+H25+H28+H30+H33+H34+H38+H42+H47+H51+H55+F59 | I18: =+I19+I25+I28+I30+I33+I34+I38+I42+I47+I51+I55+G59 | J18: =+J19+J25+J28+J30+J33+J34+J38+J42+J47+J51+J55+J59 | K18: =+K19+K25+K28+K30+K33+K34+K38+K42+K47+K51+K55+K59 | L18: =+L19+L25+L28+L30+L33+L34+L38+L42+L47+L51+L55+L59 | M18: =+M19+M25+M28+M30+M33+M34+M38+M42+M47+M51+M55+M59 | N18: =+N19+N25+N28+N30+N33+N34+N38+N42+N47+N51+N55+N59 | O18: =+O19+O25+O28+O30+O33+O34+O38+O42+O47+O51+O55+O59
A19: 1 | B19: Triển khai BTS đảm bảo hạ tầng kinh doanh | D19: =SUM(D20:D24) | E19: =+D19/5 | F19: =SUM(F20:F24) | G19: =+F19/7.5 | H19: =SUM(H20:H24) | I19: =+H19/5 | J19: =SUM(J20:J24) | K19: =+J19/7.5 | L19: =D19-H19 | M19: =E19-I19 | N19: =F19-J19 | O19: =G19-K19 | P19: 0.95 | Q19: 98%-100% | R19: 1.1 | S19: TTKTKV | T19: BQLDAHTVT kiểm soát trước khi TTKTKV phê duyệt | U19: Thanhlv4
A20: - | B20: Phát sóng vị trí mới | C20: 1. Định nghĩa: Tỉ lệ % hoàn thành các chỉ tiêu theo kế hoạch. 2. Cách tính: Tỷ lệ % hoàn thành kế hoạch x tỷ trọng từng hạng mục 3. Phương pháp: Căn cứ kết quả thực hiện so với kế hoạch giao quý/năm. 4. Hình thức báo cáo: Thông qua Phần mềm | D20: 0.3 | E20: =+D20/5 | F20: 0.5 | G20: =+F20/7.5 | H20: 0.3 | I20: 0.06 | J20: 0.5 | K20: 0.066666667 | L20: =D20-H20 | M20: =E20-I20 | N20: =F20-J20 | O20: =G20-K20 | P20: 0.95 | Q20: 98%-100% | R20: 1.1
A21: - | B21: Phát sóng trạm BTS cosite | D21: 0.1 | E21: =+D21/5 | F21: 0.1 | G21: =+F21/7.5 | H21: 0.1 | I21: 0.02 | J21: 0.1 | K21: 0.013333333 | L21: =D21-H21 | M21: =E21-I21 | N21: =F21-J21 | O21: =G21-K21 | P21: 0.95 | Q21: 98%-100% | R21: 1.1
A22: - | B22: Xây dựng đồng bộ nhà trạm | D22: 0.1 | E22: =+D22/5 | F22: 0.2 | G22: =+F22/7.5 | H22: 0.1 | I22: 0.02 | J22: 0.2 | K22: 0.026666667 | L22: =D22-H22 | M22: =E22-I22 | N22: =F22-J22 | O22: =G22-K22 | P22: 0.95 | Q22: 98%-100% | R22: 1.1
A23: - | B23: Thuê, đảm bảo mặt bằng xây dựng | D23: 0.1 | E23: 0.04 | F23: 0.2 | G23: 0.04 | H23: 0.2 | I23: 0.04 | J23: 0.3 | K23: 0.04 | L23: =D23-H23 | M23: =E23-I23 | N23: =F23-J23 | O23: =G23-K23 | P23: 0.9 | Q23: 95%-98% | R23: 1
A24: - | B24: Xin Giấy phép xây dựng | D24: 0.1 | E24: =+D24/5 | F24: 0.2 | G24: =+F24/7.5 | H24: 0.1 | I24: 0.02 | J24: 0.2 | K24: 0.026666667 | L24: =D24-H24 | M24: =E24-I24 | N24: =F24-J24 | O24: =G24-K24 | P24: 0.9 | Q24: 95%-98% | R24: 1
A25: 2 | B25: Triển khai Gpon đảm bảo hạ tầng kinh doanh | D25: =SUM(D26:D27) | E25: =+D25/5 | F25: =SUM(F26:F27) | G25: =+F25/7.5 | H25: =SUM(H26:H27) | I25: =+H25/5 | J25: =SUM(J26:J27) | K25: =+J25/7.5 | L25: =D25-H25 | M25: =E25-I25 | N25: =F25-J25 | O25: =G25-K25 | P25: 0.95 | Q25: 98%-100% | R25: 1.1 | S25: TTKTKV | T25: BQLDAHTVT kiểm soát trước khi TTKTKV phê duyệt | U25: Thanhlv4
A26: - | B26: Nhập NIMS cổng Gpon ngoài trời | C26: 1. Định nghĩa: Tỉ lệ % hoàn thành các chỉ tiêu theo kế hoạch. 2. Cách tính: Tỷ lệ % hoàn thành kế hoạch x tỷ trọng từng hạng mục 3. Phương pháp: Căn cứ kết quả thực hiện so với kế hoạch giao quý/năm. 4. Hình thức báo cáo: Thông qua Phần mềm | D26: 0.2 | E26: =+D26/5 | F26: 0.4 | G26: =+F26/7.5 | H26: 0.3 | I26: 0.06 | J26: 0.5 | K26: 0.066666667 | L26: =D26-H26 | M26: =E26-I26 | N26: =F26-J26 | O26: =G26-K26 | P26: 0.95 | Q26: 98%-100% | R26: 1.1
A27: - | B27: Nhập NIMS cổng Gpon trong nhà | D27: 0.2 | E27: =+D27/5 | F27: 0.3 | G27: =+F27/7.5 | H27: 0.2 | I27: 0.04 | J27: 0.3 | K27: 0.04 | L27: =D27-H27 | M27: =E27-I27 | N27: =F27-J27 | O27: =G27-K27 | P27: 0.95 | Q27: 98%-100% | R27: 1.1 | U27: dungnh2
A28: 3 | B28: Triển khai dự án Tòa nhà - KCN - KĐT đảm bảo kinh doanh | D28: =SUM(D29:D29) | E28: =+D28/5 | F28: =SUM(F29:F29) | G28: =+F28/7.5 | H28: =SUM(H29:H29) | I28: =+H28/5 | J28: =SUM(J29:J29) | K28: =+J28/7.5 | L28: =D28-H28 | M28: =E28-I28 | N28: =F28-J28 | O28: =G28-K28 | P28: 0.95 | Q28: 98%-100% | R28: 1.1 | S28: TTKTKV | T28: BQLDAHTVT kiểm soát trước khi TTKTKV phê duyệt | U28: dungnh2
A29: - | B29: Hoàn thành triển khai dự án | C29: 1. Định nghĩa: Tỉ lệ % hoàn thành các chỉ tiêu theo kế hoạch. 2. Cách tính: Tỷ lệ % hoàn thành kế hoạch x tỷ trọng từng hạng mục 3. Phương pháp: Căn cứ kết quả thực hiện so với kế hoạch giao quý/năm. 4. Hình thức báo cáo: Thông qua Phần mềm | D29: 0.2 | E29: =+D29/5 | F29: 0.3 | G29: =+F29/7.5 | H29: 0.2 | I29: 0.04 | J29: 0.3 | K29: 0.04 | L29: =D29-H29 | M29: =E29-I29 | N29: =F29-J29 | O29: =G29-K29 | P29: 0.95 | Q29: 98%-100% | R29: 1.1 | V29: Giảm 0,1
A30: 4 | B30: Triển khai truyền dẫn (Ngầm/treo) | C30: 1. Định nghĩa: Tỉ lệ % hoàn thành các chỉ tiêu theo kế hoạch. 2. Cách tính: Tỷ lệ % hoàn thành kế hoạch x tỷ trọng từng hạng mục 3. Phương pháp: Căn cứ kết quả thực hiện so với kế hoạch giao quý/năm. 4. Hình thức báo cáo: Thông qua Phần mềm | D30: =SUM(D31:D32) | E30: =+D30/5 | F30: =SUM(F31:F32) | G30: =+F30/7.5 | H30: =SUM(H31:H32) | I30: =+H30/5 | J30: =SUM(J31:J32) | K30: =+J30/7.5 | L30: =D30-H30 | M30: =E30-I30 | N30: =F30-J30 | O30: =G30-K30 | P30: 0.95 | Q30: 98%-100% | R30: 1.1 | S30: TTKTKV | T30: BQLDAHTVT kiểm soát trước khi TTKTKV phê duyệt | U30: Thanhlv4
A31: - | B31: Triển khai km cáp ngầm | D31: 0.1 | E31: =+D31/5 | F31: 0.2 | G31: =+F31/7.5 | H31: 0.1 | I31: 0.02 | J31: 0.2 | K31: 0.026666667 | L31: =D31-H31 | M31: =E31-I31 | N31: =F31-J31 | O31: =G31-K31 | P31: 0.95 | Q31: 98%-100% | R31: 1.1
A32: - | B32: Hoàn thành tuyến truyền dẫn ngầm | D32: 0.1 | E32: =+D32/5 | F32: 0.2 | G32: =+F32/7.5 | H32: 0.2 | I32: 0.04 | J32: 0.3 | K32: 0.04 | L32: =D32-H32 | M32: =E32-I32 | N32: =F32-J32 | O32: =G32-K32 | P32: 0.95 | Q32: 98%-100% | R32: 1.1
A33: 5 | B33: Triển khai các kế hoạch NCCLM, LHSK, thu/rút thiết bị/cơ điện…. | C33: 1. Định nghĩa: Trung bình % kế hoạch hoàn thành 2. Cách tính: Σ tỷ lệ hoàn thành x tỷ trọng 3. Phương pháp đánh giá: Căn cứ theo kết quả thực hiện so với kế hoạch 4. Hình thức báo cáo: Thông qua biên bản bàn giao hoàn thành công việc. | D33: 0.3 | E33: =+D33/5 | F33: 0.4 | G33: =+F33/7.5 | H33: 0.3 | I33: =+H33/5 | J33: 0.4 | K33: =+J33/7.5 | L33: =D33-H33 | M33: =E33-I33 | N33: =F33-J33 | O33: =G33-K33 | P33: 0.9 | Q33: 95%-98% | R33: 1 | S33: TTKTKV | T33: BQLDAHTVT kiểm soát trước khi TTKTKV phê duyệt | U33: Thanhlv4
A34: 6 | B34: Nghiệm thu/Giảm tồn tài sản | C34: 1. Định nghĩa: Tỉ lệ % hoàn thành các chỉ tiêu theo kế hoạch 2. Cách tính: Tỷ lệ % hoàn thành kế hoạch x tỷ trọng từng hạng mục 3. Phương pháp đánh giá: - Căn cứ theo kết quả thực hiện so với kế hoạch - Căn cứ kết quả nghiệm thu hạng mục BTS, Ngầm, CĐBR, Củng cố phải đạt tổi thiểu 90% thì với được tính điểm (điều kiện bắt buộc) 4. Hình thức báo cáo: Thông qua biên bản bàn giao hoàn thành công việc. | D34: =SUM(D35:D37) | E34: =+D34/5 | F34: =SUM(F35:F37) | G34: =+F34/7.5 | H34: =SUM(H35:H37) | I34: =+H34/5 | J34: =SUM(J35:J37) | K34: =+J34/7.5 | L34: =D34-H34 | M34: =E34-I34 | N34: =F34-J34 | O34: =G34-K34 | P34: 0.9 | Q34: 95%-98% | R34: 1 | S34: TTKTKV | T34: BQLDAHTVT kiểm soát trước khi TTKTKV phê duyệt | U34: Thanhlv4
A35: - | B35: Nghiệm thu ĐVSD công trình | D35: 0.2 | E35: =+D35/5 | F35: 0.4 | G35: =+F35/7.5 | H35: 0.3 | I35: 0.06 | J35: 0.4 | K35: 0.053333333 | L35: =D35-H35 | M35: =E35-I35 | N35: =F35-J35 | O35: =G35-K35 | P35: 0.95 | Q35: 98%-100% | R35: 1.1 | S35: TTKTKV | U35: Thanhlv4 | V35: Giảm 0,1
A36: - | B36: Hoàn thành ký đối soát vật tư A cấp (4A) | D36: 0.1 | E36: =+D36/5 | F36: 0.2 | G36: =+F36/7.5 | H36: 0.2 | I36: 0.04 | J36: 0.4 | K36: 0.053333333 | L36: =D36-H36 | M36: =E36-I36 | N36: =F36-J36 | O36: =G36-K36 | P36: 0.95 | Q36: 98%-100% | R36: 1.1 | S36: TTKTKV | U36: Thanhlv4 | V36: Giảm 0,1
A37: - | B37: Bàn giao tài sản công trình | D37: 0.2 | E37: =+D37/5 | F37: 0.4 | G37: =+F37/7.5 | H37: 0.2 | I37: 0.04 | J37: 0.6 | K37: 0.08 | L37: =D37-H37 | M37: =E37-I37 | N37: =F37-J37 | O37: =G37-K37 | P37: 0.9 | Q37: 95%-98% | R37: 1 | S37: TTKTKV | U37: Thanhlv4 | V37: Giảm 0,1
A38: 7 | B38: Kiểm soát chất lượng công trình | C38: 1. Định nghĩa: Tỉ lệ % hoàn thành các chỉ tiêu theo kế hoạch 2. Cách tính: - Điểm nề nếp và khắc phục lỗi: % hoàn thành kế hoạch x tỷ trọng từng hạng mục - Điểm kiểm tra KPI lỗi: Không đạt KPI => Trừ hết quỹ điểm 3. Phương pháp đánh giá: Căn cứ theo kết quả thực hiện so với kế hoạch 4. Hình thức báo cáo: Thông qua phần mềm và biên bản kiểm tra | D38: =SUM(D39:D41) | E38: =+D38/5 | F38: =SUM(F39:F41) | G38: =+F38/7.5 | H38: =SUM(H39:H41) | I38: =+H38/5 | J38: =SUM(J39:J41) | K38: =+J38/7.5 | L38: =D38-H38 | M38: =E38-I38 | N38: =F38-J38 | O38: =G38-K38 | P38: 0.9 | Q38: 95%-98% | R38: 1 | S38: TTKTKV | T38: BQLDAHTVT kiểm soát trước khi TTKTKV phê duyệt | U38: Thanhlv4
A39: - | B39: Nề nếp hình ảnh: Giao NVGS; Cập nhật, phê duyệt hình ảnh trên PM QLCL | D39: 0.1 | E39: =+D39/5 | F39: 0.2 | G39: =+F39/7.5 | H39: 0.1 | I39: 0.02 | J39: 0.2 | K39: 0.026666667 | L39: =D39-H39 | M39: =E39-I39 | N39: =F39-J39 | O39: =G39-K39 | P39: 0.9 | Q39: 95%-98% | R39: 1
A40: - | B40: Khắc phục lỗi công trình theo KH | D40: 0.1 | E40: =+D40/5 | F40: 0.2 | G40: =+F40/7.5 | H40: 0.1 | I40: 0.02 | J40: 0.2 | K40: 0.026666667 | L40: =D40-H40 | M40: =E40-I40 | N40: =F40-J40 | O40: =G40-K40 | P40: 0.9 | Q40: 95%-98% | R40: 1
...

Sheet MetaTH
